Workbook

Sheet Plano de Contas
A1: CONTA | B1: S | C1: D E N O M I N A C A O | D1: Natureza | E1: Classificação | F1: Grupo | G1: CP x LP | H1: Caracteres | I1: cod | J1: Grupo conta | K1: Grupo Relatório | L1: Revisão Analítica | M1: Notas | N1: Detalhe
A2: 1 | B2: S | C2: ATIVO | D2: D | E2: =LEFT(A2,1) -> 1 | F2: Ativo | G2: - | H2: =LEN(A2) -> 1 | I2: =IF(H2=11,A2,"-") -> - | J2: =IF(H2<11,C2,IF(I2<>"-",C2,J1)) -> ATIVO | S2: =C2='Plano de Contas sem ponto'!C2 -> TRUE
A3: 1.1 | B3: S | C3: ATIVO CIRCULANTE | D3: D | E3: =LEFT(A3,1) -> 1 | F3: Ativo | G3: Curto Prazo | H3: =LEN(A3) -> 3 | I3: =IF(H3=11,A3,"-") -> - | J3: =IF(H3<11,C3,IF(I3<>"-",C3,J2)) -> ATIVO CIRCULANTE | S3: =C3='Plano de Contas sem ponto'!C3 -> TRUE
A4: 1.1.1 | B4: S | C4: DISPONIVEL | D4: D | E4: =LEFT(A4,1) -> 1 | F4: Ativo | G4: Curto Prazo | H4: =LEN(A4) -> 5 | I4: =IF(H4=11,A4,"-") -> - | J4: =IF(H4<11,C4,IF(I4<>"-",C4,J3)) -> DISPONIVEL | S4: =C4='Plano de Contas sem ponto'!C4 -> TRUE
A5: 1.1.1.01 | B5: S | C5: CAIXA | D5: D | E5: =LEFT(A5,1) -> 1 | F5: Ativo | G5: Curto Prazo | H5: =LEN(A5) -> 8 | I5: =IF(H5=11,A5,"-") -> - | J5: =IF(H5<11,C5,IF(I5<>"-",C5,J4)) -> CAIXA | S5: =C5='Plano de Contas sem ponto'!C5 -> TRUE
A6: 1.1.1.01.01 | B6: S | C6: FUNDOS FIXOS | D6: D | E6: =LEFT(A6,1) -> 1 | F6: Ativo | G6: Curto Prazo | H6: =LEN(A6) -> 11 | I6: =IF(H6=11,A6,"-") -> 1.1.1.01.01 | J6: =IF(H6<11,C6,IF(I6<>"-",C6,J5)) -> FUNDOS FIXOS | K6: Caixa e equivalentes de caixa | L6: Fundo fixo | S6: =C6='Plano de Contas sem ponto'!C6 -> TRUE
A7: 1.1.1.01.01.0001 | B7: A | C7: FUNDO FIXO - RIO | D7: D | E7: =LEFT(A7,1) -> 1 | F7: Ativo | G7: Curto Prazo | H7: =LEN(A7) -> 16 | I7: =IF(H7=11,A7,"-") -> - | J7: =IF(H7<11,C7,IF(I7<>"-",C7,J6)) -> FUNDOS FIXOS | K7: Caixa e equivalentes de caixa | L7: Fundo fixo | S7: =C7='Plano de Contas sem ponto'!C7 -> TRUE
A8: 1.1.1.01.01.0002 | B8: A | C8: FUNDO FIXO - BRASILIA | D8: D | E8: =LEFT(A8,1) -> 1 | F8: Ativo | G8: Curto Prazo | H8: =LEN(A8) -> 16 | I8: =IF(H8=11,A8,"-") -> - | J8: =IF(H8<11,C8,IF(I8<>"-",C8,J7)) -> FUNDOS FIXOS | K8: Caixa e equivalentes de caixa | L8: Fundo fixo | S8: =C8='Plano de Contas sem ponto'!C8 -> TRUE
A9: 1.1.1.01.01.0003 | B9: A | C9: FUNDO FIXO - FENAPREVI | D9: D | E9: =LEFT(A9,1) -> 1 | F9: Ativo | G9: Curto Prazo | H9: =LEN(A9) -> 16 | I9: =IF(H9=11,A9,"-") -> - | J9: =IF(H9<11,C9,IF(I9<>"-",C9,J8)) -> FUNDOS FIXOS | K9: Caixa e equivalentes de caixa | L9: Fundo fixo | S9: =C9='Plano de Contas sem ponto'!C9 -> TRUE
A10: 1.1.1.01.01.0004 | B10: A | C10: FUNDO FIXO - FENSEG | D10: D | E10: =LEFT(A10,1) -> 1 | F10: Ativo | G10: Curto Prazo | H10: =LEN(A10) -> 16 | I10: =IF(H10=11,A10,"-") -> - | J10: =IF(H10<11,C10,IF(I10<>"-",C10,J9)) -> FUNDOS FIXOS | K10: Caixa e equivalentes de caixa | L10: Fundo fixo | S10: =C10='Plano de Contas sem ponto'!C10 -> TRUE
A11: 1.1.1.01.01.0005 | B11: A | C11: FUNDO FIXO - FENASAÚDE | D11: D | E11: =LEFT(A11,1) -> 1 | F11: Ativo | G11: Curto Prazo | H11: =LEN(A11) -> 16 | I11: =IF(H11=11,A11,"-") -> - | J11: =IF(H11<11,C11,IF(I11<>"-",C11,J10)) -> FUNDOS FIXOS | K11: Caixa e equivalentes de caixa | L11: Fundo fixo | S11: =C11='Plano de Contas sem ponto'!C11 -> TRUE
A12: 1.1.1.01.01.0006 | B12: A | C12: FUNDO FIXO - FENACAP | D12: D | E12: =LEFT(A12,1) -> 1 | F12: Ativo | G12: Curto Prazo | H12: =LEN(A12) -> 16 | I12: =IF(H12=11,A12,"-") -> - | J12: =IF(H12<11,C12,IF(I12<>"-",C12,J11)) -> FUNDOS FIXOS | K12: Caixa e equivalentes de caixa | L12: Fundo fixo | S12: =C12='Plano de Contas sem ponto'!C12 -> TRUE
A13: 1.1.1.01.01.0007 | B13: A | C13: FUNDO FIXO - SINDICATO | D13: D | E13: =LEFT(A13,1) -> 1 | F13: Ativo | G13: Curto Prazo | H13: =LEN(A13) -> 16 | I13: =IF(H13=11,A13,"-") -> - | J13: =IF(H13<11,C13,IF(I13<>"-",C13,J12)) -> FUNDOS FIXOS | K13: Caixa e equivalentes de caixa | L13: Fundo fixo | S13: =C13='Plano de Contas sem ponto'!C13 -> TRUE
A14: 1.1.1.01.01.0008 | B14: A | C14: FUNDO FIXO - CNSIMO | D14: D | E14: =LEFT(A14,1) -> 1 | F14: Ativo | G14: Curto Prazo | H14: =LEN(A14) -> 16 | I14: =IF(H14=11,A14,"-") -> - | J14: =IF(H14<11,C14,IF(I14<>"-",C14,J13)) -> FUNDOS FIXOS | K14: Caixa e equivalentes de caixa | L14: Fundo fixo | S14: =C14='Plano de Contas sem ponto'!C14 -> TRUE
A15: 1.1.1.01.01.0009 | B15: A | C15: FUNDO FIXO - CNSEG | D15: D | E15: =LEFT(A15,1) -> 1 | F15: Ativo | G15: Curto Prazo | H15: =LEN(A15) -> 16 | I15: =IF(H15=11,A15,"-") -> - | J15: =IF(H15<11,C15,IF(I15<>"-",C15,J14)) -> FUNDOS FIXOS | K15: Caixa e equivalentes de caixa | L15: Fundo fixo | S15: =C15='Plano de Contas sem ponto'!C15 -> TRUE
A16: 1.1.1.01.01.0010 | B16: A | C16: FUNDO FIXO - CNSPAR | D16: D | E16: =LEFT(A16,1) -> 1 | F16: Ativo | G16: Curto Prazo | H16: =LEN(A16) -> 16 | I16: =IF(H16=11,A16,"-") -> - | J16: =IF(H16<11,C16,IF(I16<>"-",C16,J15)) -> FUNDOS FIXOS | K16: Caixa e equivalentes de caixa | L16: Fundo fixo | S16: =C16='Plano de Contas sem ponto'!C16 -> TRUE
A17: 1.1.1.02 | B17: S | C17: BANCOS | D17: D | E17: =LEFT(A17,1) -> 1 | F17: Ativo | G17: Curto Prazo | H17: =LEN(A17) -> 8 | I17: =IF(H17=11,A17,"-") -> - | J17: =IF(H17<11,C17,IF(I17<>"-",C17,J16)) -> BANCOS | K17: Caixa e equivalentes de caixa | S17: =C17='Plano de Contas sem ponto'!C17 -> TRUE
A18: 1.1.1.02.01 | B18: S | C18: BANCOS CONTA MOVIMENTO | D18: D | E18: =LEFT(A18,1) -> 1 | F18: Ativo | G18: Curto Prazo | H18: =LEN(A18) -> 11 | I18: =IF(H18=11,A18,"-") -> 1.1.1.02.01 | J18: =IF(H18<11,C18,IF(I18<>"-",C18,J17)) -> BANCOS CONTA MOVIMENTO | K18: Caixa e equivalentes de caixa | L18: Bancos conta movimento | S18: =C18='Plano de Contas sem ponto'!C18 -> TRUE
A19: 1.1.1.02.01.0001 | B19: A | C19: BCO ITAU S/A - 0477/32832 | D19: D | E19: =LEFT(A19,1) -> 1 | F19: Ativo | G19: Curto Prazo | H19: =LEN(A19) -> 16 | I19: =IF(H19=11,A19,"-") -> - | J19: =IF(H19<11,C19,IF(I19<>"-",C19,J18)) -> BANCOS CONTA MOVIMENTO | K19: Caixa e equivalentes de caixa | L19: Bancos conta movimento | S19: =C19='Plano de Contas sem ponto'!C19 -> TRUE
A20: 1.1.1.02.01.0002 | B20: A | C20: BCO ITAU S/A - 0477/34759 | D20: D | E20: =LEFT(A20,1) -> 1 | F20: Ativo | G20: Curto Prazo | H20: =LEN(A20) -> 16 | I20: =IF(H20=11,A20,"-") -> - | J20: =IF(H20<11,C20,IF(I20<>"-",C20,J19)) -> BANCOS CONTA MOVIMENTO | K20: Caixa e equivalentes de caixa | L20: Bancos conta movimento | S20: =C20='Plano de Contas sem ponto'!C20 -> TRUE
A21: 1.1.1.02.01.0003 | B21: A | C21: BCO CAIXA ECONOMICA - 0542/775715-0 | D21: D | E21: =LEFT(A21,1) -> 1 | F21: Ativo | G21: Curto Prazo | H21: =LEN(A21) -> 16 | I21: =IF(H21=11,A21,"-") -> - | J21: =IF(H21<11,C21,IF(I21<>"-",C21,J20)) -> BANCOS CONTA MOVIMENTO | K21: Caixa e equivalentes de caixa | L21: Bancos conta movimento | S21: =C21='Plano de Contas sem ponto'!C21 -> TRUE
A22: 1.1.1.02.01.0004 | B22: A | C22: BCO BRASIL S/A - 1769/410 | D22: D | E22: =LEFT(A22,1) -> 1 | F22: Ativo | G22: Curto Prazo | H22: =LEN(A22) -> 16 | I22: =IF(H22=11,A22,"-") -> - | J22: =IF(H22<11,C22,IF(I22<>"-",C22,J21)) -> BANCOS CONTA MOVIMENTO | K22: Caixa e equivalentes de caixa | L22: Bancos conta movimento | S22: =C22='Plano de Contas sem ponto'!C22 -> TRUE
A23: 1.1.1.02.01.0005 | B23: A | C23: BCO ITAU S/A - 0477/63974 | D23: D | E23: =LEFT(A23,1) -> 1 | F23: Ativo | G23: Curto Prazo | H23: =LEN(A23) -> 16 | I23: =IF(H23=11,A23,"-") -> - | J23: =IF(H23<11,C23,IF(I23<>"-",C23,J22)) -> BANCOS CONTA MOVIMENTO | K23: Caixa e equivalentes de caixa | L23: Bancos conta movimento | S23: =C23='Plano de Contas sem ponto'!C23 -> TRUE
A24: 1.1.1.02.01.0006 | B24: A | C24: BCO BRADESCO - 2373/41669 | D24: D | E24: =LEFT(A24,1) -> 1 | F24: Ativo | G24: Curto Prazo | H24: =LEN(A24) -> 16 | I24: =IF(H24=11,A24,"-") -> - | J24: =IF(H24<11,C24,IF(I24<>"-",C24,J23)) -> BANCOS CONTA MOVIMENTO | K24: Caixa e equivalentes de caixa | L24: Bancos conta movimento | S24: =C24='Plano de Contas sem ponto'!C24 -> TRUE
A25: 1.1.1.02.01.0007 | B25: A | C25: BCO BRADESCO - 2373/41818 | D25: D | E25: =LEFT(A25,1) -> 1 | F25: Ativo | G25: Curto Prazo | H25: =LEN(A25) -> 16 | I25: =IF(H25=11,A25,"-") -> - | J25: =IF(H25<11,C25,IF(I25<>"-",C25,J24)) -> BANCOS CONTA MOVIMENTO | K25: Caixa e equivalentes de caixa | L25: Bancos conta movimento | S25: =C25='Plano de Contas sem ponto'!C25 -> TRUE
A26: 1.1.1.02.01.0008 | B26: A | C26: BCO ALFA S/A 0004/31276-2 | D26: D | E26: =LEFT(A26,1) -> 1 | F26: Ativo | G26: Curto Prazo | H26: =LEN(A26) -> 16 | I26: =IF(H26=11,A26,"-") -> - | J26: =IF(H26<11,C26,IF(I26<>"-",C26,J25)) -> BANCOS CONTA MOVIMENTO | K26: Caixa e equivalentes de caixa | L26: Bancos conta movimento | S26: =C26='Plano de Contas sem ponto'!C26 -> TRUE
A27: 1.1.1.02.01.0009 | B27: A | C27: BCO BRASIL -1769/8188-4 | D27: D | E27: =LEFT(A27,1) -> 1 | F27: Ativo | G27: Curto Prazo | H27: =LEN(A27) -> 16 | I27: =IF(H27=11,A27,"-") -> - | J27: =IF(H27<11,C27,IF(I27<>"-",C27,J26)) -> BANCOS CONTA MOVIMENTO | K27: Caixa e equivalentes de caixa | L27: Bancos conta movimento | S27: =C27='Plano de Contas sem ponto'!C27 -> TRUE
A28: 1.1.1.02.01.0010 | B28: A | C28: BCO BRADESCO 1803/415754-0 GRA | D28: D | E28: =LEFT(A28,1) -> 1 | F28: Ativo | G28: Curto Prazo | H28: =LEN(A28) -> 16 | I28: =IF(H28=11,A28,"-") -> - | J28: =IF(H28<11,C28,IF(I28<>"-",C28,J27)) -> BANCOS CONTA MOVIMENTO | K28: Caixa e equivalentes de caixa | L28: Bancos conta movimento | S28: =C28='Plano de Contas sem ponto'!C28 -> TRUE
A29: 1.1.1.02.01.0011 | B29: A | C29: BCO ITAU S/A - 0477/87124-8 | D29: D | E29: =LEFT(A29,1) -> 1 | F29: Ativo | G29: Curto Prazo | H29: =LEN(A29) -> 16 | I29: =IF(H29=11,A29,"-") -> - | J29: =IF(H29<11,C29,IF(I29<>"-",C29,J28)) -> BANCOS CONTA MOVIMENTO | K29: Caixa e equivalentes de caixa | L29: Bancos conta movimento | S29: =C29='Plano de Contas sem ponto'!C29 -> TRUE
... A61: 1.1.1.02.01.0043 | B61: A | C61: BCO ITAU S/A - 0477/19735-4 - CNSPAR | D61: D | E61: =LEFT(A61,1) -> 1 | F61: Ativo | G61: Curto Prazo | H61: =LEN(A61) -> 16 | I61: =IF(H61=11,A61,"-") -> - | J61: =IF(H61<11,C61,IF(I61<>"-",C61,J60)) -> BANCOS CONTA MOVIMENTO | K61: Caixa e equivalentes de caixa | L61: Bancos conta movimento | S61: =C61='Plano de Contas sem ponto'!C61 -> TRUE
A62: 1.1.1.02.01.0044 | B62: A | C62: BCO BEPAY - BPP INSTITUIÇÕES DE PAGAMENTOS 0001/200040270-2 | D62: D | E62: =LEFT(A62,1) -> 1 | F62: Ativo | G62: Curto Prazo | H62: =LEN(A62) -> 16 | I62: =IF(H62=11,A62,"-") -> - | J62: =IF(H62<11,C62,IF(I62<>"-",C62,J59)) -> BANCOS CONTA MOVIMENTO | K62: Caixa e equivalentes de caixa | L62: Bancos conta movimento | S62: =C62='Plano de Contas sem ponto'!C62 -> TRUE
A63: 1.1.1.02.01.0045 | B63: A | C63: BCO IUGU - IUGU INSTITUIÇÕES DE PAGAMENTOS 0002/5392769-0 | D63: D | E63: =LEFT(A63,1) -> 1 | F63: Ativo | G63: Curto Prazo | H63: =LEN(A63) -> 16 | I63: =IF(H63=11,A63,"-") -> - | J63: =IF(H63<11,C63,IF(I63<>"-",C63,J60)) -> BANCOS CONTA MOVIMENTO | K63: Caixa e equivalentes de caixa | L63: Bancos conta movimento | S63: =C63='Plano de Contas sem ponto'!C63 -> TRUE
A64: 1.1.1.02.02 | B64: S | C64: INVESTIMENTOS | D64: D | E64: =LEFT(A64,1) -> 1 | F64: Ativo | G64: Curto Prazo | H64: =LEN(A64) -> 11 | I64: =IF(H64=11,A64,"-") -> 1.1.1.02.02 | J64: =IF(H64<11,C64,IF(I64<>"-",C64,J61)) -> INVESTIMENTOS | K64: Caixa e equivalentes de caixa | S64: =C64='Plano de Contas sem ponto'!C64 -> TRUE
A65: 1.1.1.02.02.0001 | B65: A | C65: INVESTIMENTOS - EQUIVALENTE DE CAIXA | D65: D | E65: =LEFT(A65,1) -> 1 | F65: Ativo | G65: Curto Prazo | H65: =LEN(A65) -> 16 | I65: =IF(H65=11,A65,"-") -> - | J65: =IF(H65<11,C65,IF(I65<>"-",C65,J64)) -> INVESTIMENTOS | K65: Caixa e equivalentes de caixa | L65: Bancos conta movimento | S65: =C65='Plano de Contas sem ponto'!C65 -> TRUE
A66: 1.1.1.03 | B66: S | C66: APLICACOES FINANCEIRAS | D66: D | E66: =LEFT(A66,1) -> 1 | F66: Ativo | G66: Curto Prazo | H66: =LEN(A66) -> 8 | I66: =IF(H66=11,A66,"-") -> - | J66: =IF(H66<11,C66,IF(I66<>"-",C66,J65)) -> APLICACOES FINANCEIRAS | K66: Caixa e equivalentes de caixa | S66: =C66='Plano de Contas sem ponto'!C66 -> TRUE
A67: 1.1.1.03.01 | B67: S | C67: TITULOS DE RENDA FIXA | D67: D | E67: =LEFT(A67,1) -> 1 | F67: Ativo | G67: Curto Prazo | H67: =LEN(A67) -> 11 | I67: =IF(H67=11,A67,"-") -> 1.1.1.03.01 | J67: =IF(H67<11,C67,IF(I67<>"-",C67,J66)) -> TITULOS DE RENDA FIXA | K67: Caixa e equivalentes de caixa | L67: Titulos de renda fixa | S67: =C67='Plano de Contas sem ponto'!C67 -> TRUE
A68: 1.1.1.03.01.0001 | B68: A | C68: CDB/CDI | D68: D | E68: =LEFT(A68,1) -> 1 | F68: Ativo | G68: Curto Prazo | H68: =LEN(A68) -> 16 | I68: =IF(H68=11,A68,"-") -> - | J68: =IF(H68<11,C68,IF(I68<>"-",C68,J67)) -> TITULOS DE RENDA FIXA | K68: Caixa e equivalentes de caixa | L68: Titulos de renda fixa | S68: =C68='Plano de Contas sem ponto'!C68 -> TRUE
A69: 1.1.1.03.02 | B69: S | C69: TITULOS RENDA VARIÁVEL | D69: D | E69: =LEFT(A69,1) -> 1 | F69: Ativo | G69: Curto Prazo | H69: =LEN(A69) -> 11 | I69: =IF(H69=11,A69,"-") -> 1.1.1.03.02 | J69: =IF(H69<11,C69,IF(I69<>"-",C69,J68)) -> TITULOS RENDA VARIÁVEL | K69: Caixa e equivalentes de caixa | L69: Titulos renda variável | S69: =C69='Plano de Contas sem ponto'!C69 -> TRUE
A70: 1.1.1.03.02.0001 | B70: A | C70: ACOES | D70: D | E70: =LEFT(A70,1) -> 1 | F70: Ativo | G70: Curto Prazo | H70: =LEN(A70) -> 16 | I70: =IF(H70=11,A70,"-") -> - | J70: =IF(H70<11,C70,IF(I70<>"-",C70,J69)) -> TITULOS RENDA VARIÁVEL | K70: Caixa e equivalentes de caixa | L70: Titulos renda variável | S70: =C70='Plano de Contas sem ponto'!C70 -> TRUE
A71: 1.1.1.03.03 | B71: S | C71: QUOTAS E FUNDOS DE INVESTIMENTOS | D71: D | E71: =LEFT(A71,1) -> 1 | F71: Ativo | G71: Curto Prazo | H71: =LEN(A71) -> 11 | I71: =IF(H71=11,A71,"-") -> 1.1.1.03.03 | J71: =IF(H71<11,C71,IF(I71<>"-",C71,J70)) -> QUOTAS E FUNDOS DE INVESTIMENTOS | K71: Caixa e equivalentes de caixa | L71: Quotas e fundos de investimentos | S71: =C71='Plano de Contas sem ponto'!C71 -> TRUE
...

Sheet Plano de Contas sem ponto
A1: CONTA | B1: S | C1: D E N O M I N A C A O | D1: Natureza | E1: Classificação | F1: Grupo | G1: CP x LP | H1: Caracteres | I1: cod | J1: Grupo conta | K1: Grupo Relatório | L1: Revisão Analítica | M1: Notas | N1: Detalhe
A2: 1 | B2: S | C2: ATIVO | D2: D | E2: 1 | F2: Ativo | G2: - | H2: 1 | I2: - | J2: ATIVO | S2: =C2='Plano de Contas'!C2 -> TRUE
A3: 11 | B3: S | C3: ATIVO CIRCULANTE | D3: D | E3: 1 | F3: Ativo | G3: Curto Prazo | H3: 3 | I3: - | J3: ATIVO CIRCULANTE | S3: =C3='Plano de Contas'!C3 -> TRUE
A4: 111 | B4: S | C4: DISPONIVEL | D4: D | E4: 1 | F4: Ativo | G4: Curto Prazo | H4: 5 | I4: - | J4: DISPONIVEL | S4: =C4='Plano de Contas'!C4 -> TRUE
A5: 11101 | B5: S | C5: CAIXA | D5: D | E5: 1 | F5: Ativo | G5: Curto Prazo | H5: 8 | I5: - | J5: CAIXA | S5: =C5='Plano de Contas'!C5 -> TRUE
A6: 1110101 | B6: S | C6: FUNDOS FIXOS | D6: D | E6: 1 | F6: Ativo | G6: Curto Prazo | H6: 11 | I6: 1.1.1.01.01 | J6: FUNDOS FIXOS | K6: Caixa e equivalentes de caixa | L6: Fundo fixo | S6: =C6='Plano de Contas'!C6 -> TRUE
A7: 11101010001 | B7: A | C7: FUNDO FIXO - RIO | D7: D | E7: 1 | F7: Ativo | G7: Curto Prazo | H7: 16 | I7: - | J7: FUNDOS FIXOS | K7: Caixa e equivalentes de caixa | L7: Fundo fixo | S7: =C7='Plano de Contas'!C7 -> TRUE
A8: 11101010002 | B8: A | C8: FUNDO FIXO - BRASILIA | D8: D | E8: 1 | F8: Ativo | G8: Curto Prazo | H8: 16 | I8: - | J8: FUNDOS FIXOS | K8: Caixa e equivalentes de caixa | L8: Fundo fixo | S8: =C8='Plano de Contas'!C8 -> TRUE
A9: 11101010003 | B9: A | C9: FUNDO FIXO - FENAPREVI | D9: D | E9: 1 | F9: Ativo | G9: Curto Prazo | H9: 16 | I9: - | J9: FUNDOS FIXOS | K9: Caixa e equivalentes de caixa | L9: Fundo fixo | S9: =C9='Plano de Contas'!C9 -> TRUE
A10: 11101010004 | B10: A | C10: FUNDO FIXO - FENSEG | D10: D | E10: 1 | F10: Ativo | G10: Curto Prazo | H10: 16 | I10: - | J10: FUNDOS FIXOS | K10: Caixa e equivalentes de caixa | L10: Fundo fixo | S10: =C10='Plano de Contas'!C10 -> TRUE
A11: 11101010005 | B11: A | C11: FUNDO FIXO - FENASAÚDE | D11: D | E11: 1 | F11: Ativo | G11: Curto Prazo | H11: 16 | I11: - | J11: FUNDOS FIXOS | K11: Caixa e equivalentes de caixa | L11: Fundo fixo | S11: =C11='Plano de Contas'!C11 -> TRUE
A12: 11101010006 | B12: A | C12: FUNDO FIXO - FENACAP | D12: D | E12: 1 | F12: Ativo | G12: Curto Prazo | H12: 16 | I12: - | J12: FUNDOS FIXOS | K12: Caixa e equivalentes de caixa | L12: Fundo fixo | S12: =C12='Plano de Contas'!C12 -> TRUE
A13: 11101010007 | B13: A | C13: FUNDO FIXO - SINDICATO | D13: D | E13: 1 | F13: Ativo | G13: Curto Prazo | H13: 16 | I13: - | J13: FUNDOS FIXOS | K13: Caixa e equivalentes de caixa | L13: Fundo fixo | S13: =C13='Plano de Contas'!C13 -> TRUE
A14: 11101010008 | B14: A | C14: FUNDO FIXO - CNSIMO | D14: D | E14: 1 | F14: Ativo | G14: Curto Prazo | H14: 16 | I14: - | J14: FUNDOS FIXOS | K14: Caixa e equivalentes de caixa | L14: Fundo fixo | S14: =C14='Plano de Contas'!C14 -> TRUE
A15: 11101010009 | B15: A | C15: FUNDO FIXO - CNSEG | D15: D | E15: 1 | F15: Ativo | G15: Curto Prazo | H15: 16 | I15: - | J15: FUNDOS FIXOS | K15: Caixa e equivalentes de caixa | L15: Fundo fixo | S15: =C15='Plano de Contas'!C15 -> TRUE
A16: 11101010010 | B16: A | C16: FUNDO FIXO - CNSPAR | D16: D | E16: 1 | F16: Ativo | G16: Curto Prazo | H16: 16 | I16: - | J16: FUNDOS FIXOS | K16: Caixa e equivalentes de caixa | L16: Fundo fixo | S16: =C16='Plano de Contas'!C16 -> TRUE
A17: 11102 | B17: S | C17: BANCOS | D17: D | E17: 1 | F17: Ativo | G17: Curto Prazo | H17: 8 | I17: - | J17: BANCOS | K17: Caixa e equivalentes de caixa | S17: =C17='Plano de Contas'!C17 -> TRUE
A18: 1110201 | B18: S | C18: BANCOS CONTA MOVIMENTO | D18: D | E18: 1 | F18: Ativo | G18: Curto Prazo | H18: 11 | I18: 1.1.1.02.01 | J18: BANCOS CONTA MOVIMENTO | K18: Caixa e equivalentes de caixa | L18: Bancos conta movimento | S18: =C18='Plano de Contas'!C18 -> TRUE
A19: 11102010001 | B19: A | C19: BCO ITAU S/A - 0477/32832 | D19: D | E19: 1 | F19: Ativo | G19: Curto Prazo | H19: 16 | I19: - | J19: BANCOS CONTA MOVIMENTO | K19: Caixa e equivalentes de caixa | L19: Bancos conta movimento | S19: =C19='Plano de Contas'!C19 -> TRUE
A20: 11102010002 | B20: A | C20: BCO ITAU S/A - 0477/34759 | D20: D | E20: 1 | F20: Ativo | G20: Curto Prazo | H20: 16 | I20: - | J20: BANCOS CONTA MOVIMENTO | K20: Caixa e equivalentes de caixa | L20: Bancos conta movimento | S20: =C20='Plano de Contas'!C20 -> TRUE
A21: 11102010003 | B21: A | C21: BCO CAIXA ECONOMICA - 0542/775715-0 | D21: D | E21: 1 | F21: Ativo | G21: Curto Prazo | H21: 16 | I21: - | J21: BANCOS CONTA MOVIMENTO | K21: Caixa e equivalentes de caixa | L21: Bancos conta movimento | S21: =C21='Plano de Contas'!C21 -> TRUE
A22: 11102010004 | B22: A | C22: BCO BRASIL S/A - 1769/410 | D22: D | E22: 1 | F22: Ativo | G22: Curto Prazo | H22: 16 | I22: - | J22: BANCOS CONTA MOVIMENTO | K22: Caixa e equivalentes de caixa | L22: Bancos conta movimento | S22: =C22='Plano de Contas'!C22 -> TRUE
A23: 11102010005 | B23: A | C23: BCO ITAU S/A - 0477/63974 | D23: D | E23: 1 | F23: Ativo | G23: Curto Prazo | H23: 16 | I23: - | J23: BANCOS CONTA MOVIMENTO | K23: Caixa e equivalentes de caixa | L23: Bancos conta movimento | S23: =C23='Plano de Contas'!C23 -> TRUE
A24: 11102010006 | B24: A | C24: BCO BRADESCO - 2373/41669 | D24: D | E24: 1 | F24: Ativo | G24: Curto Prazo | H24: 16 | I24: - | J24: BANCOS CONTA MOVIMENTO | K24: Caixa e equivalentes de caixa | L24: Bancos conta movimento | S24: =C24='Plano de Contas'!C24 -> TRUE
A25: 11102010007 | B25: A | C25: BCO BRADESCO - 2373/41818 | D25: D | E25: 1 | F25: Ativo | G25: Curto Prazo | H25: 16 | I25: - | J25: BANCOS CONTA MOVIMENTO | K25: Caixa e equivalentes de caixa | L25: Bancos conta movimento | S25: =C25='Plano de Contas'!C25 -> TRUE
A26: 11102010008 | B26: A | C26: BCO ALFA S/A 0004/31276-2 | D26: D | E26: 1 | F26: Ativo | G26: Curto Prazo | H26: 16 | I26: - | J26: BANCOS CONTA MOVIMENTO | K26: Caixa e equivalentes de caixa | L26: Bancos conta movimento | S26: =C26='Plano de Contas'!C26 -> TRUE
A27: 11102010009 | B27: A | C27: BCO BRASIL -1769/8188-4 | D27: D | E27: 1 | F27: Ativo | G27: Curto Prazo | H27: 16 | I27: - | J27: BANCOS CONTA MOVIMENTO | K27: Caixa e equivalentes de caixa | L27: Bancos conta movimento | S27: =C27='Plano de Contas'!C27 -> TRUE
A28: 11102010010 | B28: A | C28: BCO BRADESCO 1803/415754-0 GRA | D28: D | E28: 1 | F28: Ativo | G28: Curto Prazo | H28: 16 | I28: - | J28: BANCOS CONTA MOVIMENTO | K28: Caixa e equivalentes de caixa | L28: Bancos conta movimento | S28: =C28='Plano de Contas'!C28 -> TRUE
A29: 11102010011 | B29: A | C29: BCO ITAU S/A - 0477/87124-8 | D29: D | E29: 1 | F29: Ativo | G29: Curto Prazo | H29: 16 | I29: - | J29: BANCOS CONTA MOVIMENTO | K29: Caixa e equivalentes de caixa | L29: Bancos conta movimento | S29: =C29='Plano de Contas'!C29 -> TRUE
... A61: 11102010043 | B61: A | C61: BCO ITAU S/A - 0477/19735-4 - CNSPAR | D61: D | E61: 1 | F61: Ativo | G61: Curto Prazo | H61: 16 | I61: - | J61: BANCOS CONTA MOVIMENTO | K61: Caixa e equivalentes de caixa | L61: Bancos conta movimento | S61: =C61='Plano de Contas'!C61 -> TRUE
A62: 11102010044 | B62: A | C62: BCO BEPAY - BPP INSTITUIÇÕES DE PAGAMENTOS 0001/200040270-2 | D62: D | E62: =LEFT(A62,1) -> 1 | F62: Ativo | G62: Curto Prazo | H62: =LEN(A62) -> 11 | I62: - | J62: =IF(H62<11,C62,IF(I62<>"-",C62,J59)) -> BANCOS CONTA MOVIMENTO | K62: Caixa e equivalentes de caixa | L62: Bancos conta movimento | S62: =C62='Plano de Contas'!C62 -> TRUE
A63: 11102010045 | B63: A | C63: BCO IUGU - IUGU INSTITUIÇÕES DE PAGAMENTOS 0002/5392769-0 | D63: D | E63: =LEFT(A63,1) -> 1 | F63: Ativo | G63: Curto Prazo | H63: =LEN(A63) -> 11 | I63: - | J63: =IF(H63<11,C63,IF(I63<>"-",C63,J60)) -> BANCOS CONTA MOVIMENTO | K63: Caixa e equivalentes de caixa | L63: Bancos conta movimento | S63: =C63='Plano de Contas'!C63 -> TRUE
A64: 1110202 | B64: S | C64: INVESTIMENTOS | D64: D | E64: 1 | F64: Ativo | G64: Curto Prazo | H64: 11 | I64: 1.1.1.02.02 | J64: INVESTIMENTOS | K64: Caixa e equivalentes de caixa | S64: =C64='Plano de Contas'!C64 -> TRUE
A65: 11102020001 | B65: A | C65: INVESTIMENTOS - EQUIVALENTE DE CAIXA | D65: D | E65: 1 | F65: Ativo | G65: Curto Prazo | H65: 16 | I65: - | J65: INVESTIMENTOS | K65: Caixa e equivalentes de caixa | L65: Bancos conta movimento | S65: =C65='Plano de Contas'!C65 -> TRUE
A66: 11103 | B66: S | C66: APLICACOES FINANCEIRAS | D66: D | E66: 1 | F66: Ativo | G66: Curto Prazo | H66: 8 | I66: - | J66: APLICACOES FINANCEIRAS | K66: Caixa e equivalentes de caixa | S66: =C66='Plano de Contas'!C66 -> TRUE
A67: 1110301 | B67: S | C67: TITULOS DE RENDA FIXA | D67: D | E67: 1 | F67: Ativo | G67: Curto Prazo | H67: 11 | I67: 1.1.1.03.01 | J67: TITULOS DE RENDA FIXA | K67: Caixa e equivalentes de caixa | L67: Titulos de renda fixa | S67: =C67='Plano de Contas'!C67 -> TRUE
A68: 11103010001 | B68: A | C68: CDB/CDI | D68: D | E68: 1 | F68: Ativo | G68: Curto Prazo | H68: 16 | I68: - | J68: TITULOS DE RENDA FIXA | K68: Caixa e equivalentes de caixa | L68: Titulos de renda fixa | S68: =C68='Plano de Contas'!C68 -> TRUE
A69: 1110302 | B69: S | C69: TITULOS RENDA VARIÁVEL | D69: D | E69: 1 | F69: Ativo | G69: Curto Prazo | H69: 11 | I69: 1.1.1.03.02 | J69: TITULOS RENDA VARIÁVEL | K69: Caixa e equivalentes de caixa | L69: Titulos renda variável | S69: =C69='Plano de Contas'!C69 -> TRUE
A70: 11103020001 | B70: A | C70: ACOES | D70: D | E70: 1 | F70: Ativo | G70: Curto Prazo | H70: 16 | I70: - | J70: TITULOS RENDA VARIÁVEL | K70: Caixa e equivalentes de caixa | L70: Titulos renda variável | S70: =C70='Plano de Contas'!C70 -> TRUE
A71: 1110303 | B71: S | C71: QUOTAS E FUNDOS DE INVESTIMENTOS | D71: D | E71: 1 | F71: Ativo | G71: Curto Prazo | H71: 11 | I71: 1.1.1.03.03 | J71: QUOTAS E FUNDOS DE INVESTIMENTOS | K71: Caixa e equivalentes de caixa | L71: Quotas e fundos de investimentos | S71: =C71='Plano de Contas'!C71 -> TRUE
...

Sheet Centro de lucro
A1: Centro de Custo | B1: Descrição MXM | C1: Gerência | D1: Superintendência | E1: Diretoria | F1: Classificação BP e DRE | G1: ESTRUTURA | H1: CÓDIGO GERÊNCIA | I1: CÓDIGO SUPERINTÊNDENCIA | J1: CÓDIGO DIRETORIA
A2: F220000001 | B2: ASSESSORIA | C2: ASSESSORIA | D2: ASSESSORIA | E2: ASSESSORIA | F2: 0 | H2: ASLG | I2: ASLG | J2: ASLG
A3: F100000000 | B3: CONSELHO DIRETOR | C3: CONSELHO DIRETOR | D3: CONSELHO DIRETOR | E3: CONSELHO DIRETOR | F3: 0 | H3: CONSELHO DIRETOR | I3: CONSELHO DIRETOR | J3: CONSELHO DIRETOR
A4: F200000000 | B4: PRESIDÊNCIA | C4: PRESIDENCIA | D4: PRESIDENCIA | E4: PRESIDENCIA | F4: SISEG | G4: FPR0001 | H4: PRESI | I4: PRESI | J4: PRESI
A5: F200000001 | B5: SECRETARIA GERAL E GOV. CORPORATIVA | C5: SECRETARIA GERAL E GOVERNANÇA CORPORATIVA | D5: SECRETARIA GERAL E GOVERNANÇA CORPORATIVA | E5: SUPERINTENDÊNCIA EXECUTIVA DE COORDENAÇÃO DO GABINETE | F5: 0 | G5: FSU0113 | H5: SEGER | I5: SEGER | J5: SUGAB
A6: F200000002 | B6: CONTROLES INTERNOS E COMPLIANCE | C6: CONTROLES INTERNOS E COMPLIANCE | D6: PRESIDENCIA | E6: PRESIDENCIA | F6: 0 | H6: CICOM | I6: PRESI | J6: PRESI
A7: F200100000 | B7: SUP. EXEC. DE COORDENAÇÃO DE GABINETE | C7: SUPERINTENDÊNCIA EXECUTIVA DE COORDENAÇÃO DO GABINETE | D7: SUPERINTENDÊNCIA EXECUTIVA DE COORDENAÇÃO DO GABINETE | E7: SUPERINTENDÊNCIA EXECUTIVA DE COORDENAÇÃO DO GABINETE | F7: 0 | G7: FSE0105 | H7: SUGAB | I7: SUGAB | J7: SUGAB
A8: F203000000 | B8: SUP. EXEC. DE COMUNICAÇÃO E MARKETING | C8: SUPERINTENDÊNCIA EXECUTIVA DE COMUNICAÇÃO E MARKETING | D8: SUPERINTENDÊNCIA EXECUTIVA DE COMUNICAÇÃO E MARKETING | E8: SUPERINTENDÊNCIA EXECUTIVA DE COMUNICAÇÃO E MARKETING | F8: 0 | G8: FSE0104 | H8: SUCOM | I8: SUCOM | J8: SUCOM
A9: F203000003 | B9: CEDOM | C9: CENTRO DE DOCUMENTAÇÃO E MEMÓRIA | D9: SUPERINTENDÊNCIA EXECUTIVA DE COMUNICAÇÃO E MARKETING | E9: SUPERINTENDÊNCIA EXECUTIVA DE COMUNICAÇÃO E MARKETING | F9: 0 | H9: GEDOM | I9: SUCOM | J9: SUCOM
A10: F203000004 | B10: REVISTA DE SEGUROS | C10: REVISTA DE SEGUROS | D10: SUPERINTENDÊNCIA EXECUTIVA DE COMUNICAÇÃO E MARKETING | E10: SUPERINTENDÊNCIA EXECUTIVA DE COMUNICAÇÃO E MARKETING | F10: 0 | H10: REVSEG | I10: SUCOM | J10: SUCOM
A11: F203000005 | B11: GERÊNCIA DE COMUNICAÇÃO | C11: GERÊNCIA DE COMUNICAÇÃO | D11: SUPERINTENDÊNCIA EXECUTIVA DE COMUNICAÇÃO E MARKETING | E11: SUPERINTENDÊNCIA EXECUTIVA DE COMUNICAÇÃO E MARKETING | F11: 0 | G11: FGE0129 | H11: GECOMUN | I11: SUCOM | J11: SUCOM
A12: F203000006 | B12: GERÊNCIA DE R. C /IMPRENSA E PUBLICAÇÕES | C12: GERÊNCIA DE RELAÇÕES COM IMPRENSA E PUBLICAÇÕES | D12: SUPERINTENDÊNCIA EXECUTIVA DE COMUNICAÇÃO E MARKETING | E12: SUPERINTENDÊNCIA EXECUTIVA DE COMUNICAÇÃO E MARKETING | F12: 0 | G12: GERIN | H12: GERIN | I12: SUCOM | J12: SUCOM
A13: F203000007 | B13: GERÊNCIA DE MARKETING | C13: GERÊNCIA DE MARKETING | D13: SUPERINTENDÊNCIA EXECUTIVA DE COMUNICAÇÃO E MARKETING | E13: SUPERINTENDÊNCIA EXECUTIVA DE COMUNICAÇÃO E MARKETING | F13: 0 | G13: FGE0131 | H13: GEMKT | I13: SUCOM | J13: SUCOM
A14: F250000000 | B14: DIRETORIA DE RELAÇÕES INSTITUCIONAIS | C14: DIRETORIA DE RELAÇÕES INSTITUCIONAIS | D14: DIRETORIA DE RELAÇÕES INSTITUCIONAIS | E14: DIRETORIA DE RELAÇÕES INSTITUCIONAIS | F14: 0 | G14: FDIRIN | H14: DIRIN | I14: DIRIN | J14: DIRIN
A15: F251100000 | B15: SUPERINTENDÊNCIA DE REL. INSTITUCIONAIS | C15: SUPERINTENDÊNCIA DE RELAÇÕES INSTITUCIONAIS | D15: SUPERINTENDÊNCIA DE RELAÇÕES INSTITUCIONAIS | E15: DIRETORIA DE RELAÇÕES INSTITUCIONAIS | F15: 0 | G15: FSU0201 | H15: SURIN | I15: SURIN | J15: DIRIN
A16: F251101000 | B16: GERÊNCIA ADMINISTRATIVA - DF | C16: SUPERINTENDÊNCIA DE RELAÇÕES INSTITUCIONAIS | D16: SUPERINTENDÊNCIA DE RELAÇÕES INSTITUCIONAIS | E16: DIRETORIA DE RELAÇÕES INSTITUCIONAIS | F16: 0 | H16: SURIN | I16: SURIN | J16: DIRIN
A17: F251102000 | B17: GERÊNCIA DE REL C/ ESTADOS E MUNICÍPIOS | C17: GERÊNCIA DE RELAÇÕES COM ESTADOS E MUNICÍPIOS | D17: SUPERINTENDÊNCIA DE RELAÇÕES INSTITUCIONAIS | E17: DIRETORIA DE RELAÇÕES INSTITUCIONAIS | F17: 0 | G17: FGE0201 | H17: GEREM | I17: SURIN | J17: DIRIN
A18: F251103000 | B18: GERÊNCIA DE RELAÇÕES COM SENADO | C18: GERÊNCIA DE RELAÇÕES COM SENADO | D18: SUPERINTENDÊNCIA DE RELAÇÕES INSTITUCIONAIS | E18: DIRETORIA DE RELAÇÕES INSTITUCIONAIS | F18: 0 | G18: FGE0202 | H18: GERSEN | I18: SURIN | J18: DIRIN
A19: F251104000 | B19: GERÊNCIA DE RELAÇÕES COM A CÂMARA | C19: GERÊNCIA DE RELAÇÕES COM A CÂMARA | D19: SUPERINTENDÊNCIA DE RELAÇÕES INSTITUCIONAIS | E19: DIRETORIA DE RELAÇÕES INSTITUCIONAIS | F19: 0 | G19: FGE0203 | H19: GERCAM | I19: SURIN | J19: DIRIN
A20: F251105000 | B20: COORDENAÇÃO ADMINISTRATIVA DF | C20: SUPERINTENDÊNCIA DE RELAÇÕES INSTITUCIONAIS | D20: SUPERINTENDÊNCIA DE RELAÇÕES INSTITUCIONAIS | E20: DIRETORIA DE RELAÇÕES INSTITUCIONAIS | F20: 0 | H20: SURIN | I20: SURIN | J20: DIRIN
A21: F310000000 | B21: DIRETORIA JURÍDICA | C21: DIRETORIA JURÍDICA | D21: DIRETORIA JURÍDICA | E21: DIRETORIA JURÍDICA | F21: 0 | G21: FGT0101 | H21: DIJUR | I21: DIJUR | J21: DIJUR
A22: F311100000 | B22: SUPERINTENDÊNCIA JURÍDICA | C22: SUPERINTENDÊNCIA JURÍDICA | D22: SUPERINTENDÊNCIA JURÍDICA | E22: DIRETORIA JURÍDICA | F22: 0 | G22: FSU0101 | H22: SEJUR | I22: SEJUR | J22: DIJUR
A23: F311100001 | B23: ASSESSORIA JURÍDICA | C23: ASSESSORIA JURÍDICA | D23: SUPERINTENDÊNCIA JURÍDICA | E23: DIRETORIA JURÍDICA | F23: 0 | H23: ASSESSORIA JURÍDICA | I23: SEJUR | J23: DIJUR
A24: F311101000 | B24: GERÊNCIA DE CONTENCIOSO | C24: GERÊNCIA DE CONTENCIOSO | D24: SUPERINTENDÊNCIA JURÍDICA | E24: DIRETORIA JURÍDICA | F24: 0 | G24: FGE0101 | H24: GECOS | I24: SEJUR | J24: DIJUR
A25: F311102000 | B25: GERÊNCIA DE CONSULTORIAS | C25: GERÊNCIA DE CONSULTORIAS | D25: SUPERINTENDÊNCIA JURÍDICA | E25: DIRETORIA JURÍDICA | F25: Outras | G25: FGE0102 | H25: GECON | I25: SEJUR | J25: DIJUR
A26: F311103000 | B26: GERÊNCIA JURÍDICA CORP., DE NEGÓCIOS | C26: GERÊNCIA JURÍDICA CORP., DE NEGÓCIOS | D26: SUPERINTENDÊNCIA JURÍDICA | E26: DIRETORIA JURÍDICA | F26: Outras | G26: FGE0136 | H26: GJNECO | I26: SEJUR | J26: DIJUR
A27: F320000000 | B27: DIRETORIA DE SUSTENTABILIDADE E CONSUMO | C27: DIRETORIA DE SUSTENTABILIDADE E CONSUMO | D27: DIRETORIA DE SUSTENTABILIDADE E CONSUMO | E27: DIRETORIA DE SUSTENTABILIDADE E CONSUMO | F27: 0 | G27: FGT0102 | H27: DISEC | I27: DISEC | J27: DISEC
A28: F321100000 | B28: SUPERINTENDÊNCIA DE EVENTOS | C28: SUPERINTENDÊNCIA DE EVENTOS | D28: SUPERINTENDÊNCIA DE EVENTOS | E28: SUPERINTENDÊNCIA EXECUTIVA DE COORDENAÇÃO DO GABINETE | F28: Outras | G28: FSU0106 | H28: SUPEV | I28: SUPEV | J28: SUGAB
A29: F321101000 | B29: GERÊNCIA DE EVENTOS | C29: GERÊNCIA DE EVENTOS | D29: SUPERINTENDÊNCIA DE EVENTOS | E29: SUPERINTENDÊNCIA EXECUTIVA DE COORDENAÇÃO DO GABINETE | F29: 0 | G29: FGE0124 | H29: GEEVE | I29: SUPEV | J29: SUGAB
A30: F321102000 | B30: GERÊNCIA DE PROJETOS INSTITUCIONAIS | C30: GERÊNCIA DE PROJETOS INSTITUCIONAIS | D30: SUPERINTENDÊNCIA DE EVENTOS | E30: SUPERINTENDÊNCIA EXECUTIVA DE COORDENAÇÃO DO GABINETE | F30: 0 | G30: FGE204 | H30: GEPIT | I30: SUPEV | J30: SUGAB
A31: F330000000 | B31: DIRET. DE A. CORP. E REL. SINDICAIS | C31: DIRETORIA DE ASSUNTOS CORPORATIVOS E RELAÇÕES SINDICAIS | D31: DIRETORIA DE ASSUNTOS CORPORATIVOS E RELAÇÕES SINDICAIS | E31: DIRETORIA DE ASSUNTOS CORPORATIVOS E RELAÇÕES SINDICAIS | F31: 0 | G31: FDAFC | H31: DICOR | I31: DICOR | J31: DICOR
A32: F331000000 | B32: DIRETORIA DE SERVIÇOS AS ASSOCIADAS | C32: DIRETORIA DE SERVIÇOS AS ASSOCIADAS | D32: DIRETORIA DE SERVIÇOS AS ASSOCIADAS | E32: DIRETORIA DE SERVIÇOS AS ASSOCIADAS | G32: FDS0103 | H32: DISERV | I32: DISERV | J32: DISERV
A33: F331001000 | B33: GERÊNCIA DE SEGURANÇA DA INFORMAÇÃO | C33: GERÊNCIA DE SEGURANÇA DA INFORMAÇÃO | D33: DIRETORIA DE SERVIÇOS AS ASSOCIADAS | E33: DIRETORIA DE SERVIÇOS AS ASSOCIADAS | H33: GESEG | I33: DISERV | J33: DISERV
A34: F331101000 | B34: GERÊNCIA DE PREVENÇÃO E COMBATE A FRAUDE | C34: GERÊNCIA DE PREVENÇÃO E COMBATE A FRAUDE | D34: SUPERINTENDÊNCIA DE PRODUTOS E OPERAÇÕES | E34: DIRETORIA DE SERVIÇOS AS ASSOCIADAS | F34: Sistema Nacional de Gravames - SNG | G34: FGE0114 | H34: GEPCF | I34: SUPRO | J34: DISERV
A35: F331101001 | B35: FORNEC. DE INF. P/ PROTEÇÃO AO SEGURO | C35: GERÊNCIA DE PREVENÇÃO E COMBATE A FRAUDE | D35: SUPERINTENDÊNCIA DE PRODUTOS E OPERAÇÕES | E35: DIRETORIA DE SERVIÇOS AS ASSOCIADAS | F35: SISEG | G35: FGE0114 | H35: FORINF | I35: SUPRO | J35: DISERV
A36: F331101002 | B36: ASSINATURAS E REGRAS | C36: GERÊNCIA DE PREVENÇÃO E COMBATE A FRAUDE | D36: SUPERINTENDÊNCIA DE PRODUTOS E OPERAÇÕES | E36: DIRETORIA DE SERVIÇOS AS ASSOCIADAS | F36: SISEG | G36: FGE0114 | H36: ASSINT | I36: SUPRO | J36: DISERV
A37: F331101003 | B37: PROCEDIMENTOS CRIMINAIS | C37: GERÊNCIA DE PREVENÇÃO E COMBATE A FRAUDE | D37: SUPERINTENDÊNCIA DE PRODUTOS E OPERAÇÕES | E37: DIRETORIA DE SERVIÇOS AS ASSOCIADAS | F37: SISEG | G37: FGE0114 | H37: PROCED | I37: SUPRO | J37: DISERV
A38: F331101004 | B38: PROCEDIMENTOS CRIMINAIS - AUTO | C38: GERÊNCIA DE PREVENÇÃO E COMBATE A FRAUDE | D38: SUPERINTENDÊNCIA DE PRODUTOS E OPERAÇÕES | E38: DIRETORIA DE SERVIÇOS AS ASSOCIADAS | F38: SISEG | G38: FGE0114 | H38: PROCED | I38: SUPRO | J38: DISERV
A39: F331101005 | B39: PROCEDIMENTOS CRIMINAIS - PATRIMONIAL | C39: GERÊNCIA DE PREVENÇÃO E COMBATE A FRAUDE | D39: SUPERINTENDÊNCIA DE PRODUTOS E OPERAÇÕES | E39: DIRETORIA DE SERVIÇOS AS ASSOCIADAS | F39: SISEG | G39: FGE0114 | H39: PROCED | I39: SUPRO | J39: DISERV
A40: F331101006 | B40: PROCEDIMENTOS CRIMINAIS - TRANSPORTES | C40: GERÊNCIA DE PREVENÇÃO E COMBATE A FRAUDE | D40: SUPERINTENDÊNCIA DE PRODUTOS E OPERAÇÕES | E40: DIRETORIA DE SERVIÇOS AS ASSOCIADAS | F40: SISEG | G40: FGE0114 | H40: PROCED | I40: SUPRO | J40: DISERV
...

Sheet Fluxo de caixa
A1: Classificação das contas do fluxo de caixa
A3: Descrição | B3: Grupo Relatório | C3: Revisão Analítica | D3: Notas
A4: Receita de Inscrições | B4: Receita operacional líquida | C4: Outras receitas | D4: Eventos
A5: Aluguel | B5: Receita operacional líquida | C5: Outras receitas | D5: Receita de aluguéis
A6: Contribuição Assistencial | B6: Receita operacional líquida | C6: Outras receitas | D6: Contribuição sindical
A7: Outros (Recto Duplicidade, des | B7: Receita operacional líquida | C7: Outras receitas | D7: Outras receitas
A8: Receita de Patrocinios | B8: Receita operacional líquida | C8: Outras receitas | D8: Eventos
A9: Recuperação Despesas - Outras | B9: Receita operacional líquida | C9: Outras receitas | D9: Outras receitas
A10: Rendimento CDB | B10: Receitas financeiras | C10: Receitas de aplicações financeiras | D10: Receitas de aplicações financeiras
A11: Rendimento Fundos | B11: Receitas financeiras | C11: Receitas de aplicações financeiras | D11: Receitas de aplicações financeiras
A12: Rendimento Outras Aplicações | B12: Receitas financeiras | C12: Receitas de aplicações financeiras | D12: Receitas de aplicações financeiras
A13: SIRCOF | B13: Receita operacional líquida | C13: Sistema de contratos | D13: Sistema de Contratos (Ex-Sircof)
A14: SISEG | B14: Receita operacional líquida | C14: Sistema de contratos | D14: SISEG
... A148: IOF sobre invest financeiros | B148: Despesas financeiras | C148: Outras despesas financeiras | D148: Outras despesas financeiras
